{
 "cells": [
  {
   "cell_type": "code",
   "execution_count": 1,
   "metadata": {},
   "outputs": [],
   "source": [
    "import logging\n",
    "import os\n",
    "import telegram\n",
    "from telegram import Update\n",
    "from telegram.ext import Updater, CommandHandler, MessageHandler, Filters, CallbackContext\n"
   ]
  },
  {
   "cell_type": "code",
   "execution_count": 2,
   "metadata": {},
   "outputs": [],
   "source": [
    "from keras.preprocessing.image import img_to_array\n",
    "def convert_image_to_array(image_dir):\n",
    "    try:\n",
    "        image = cv2.imread(image_dir)\n",
    "        if image is not None :\n",
    "            image = cv2.resize(image, default_image_size)   \n",
    "            return img_to_array(image)\n",
    "        else :\n",
    "            return np.array([])\n",
    "    except Exception as e:\n",
    "        print(f\"Error : {e}\")\n",
    "        return None"
   ]
  },
  {
   "cell_type": "code",
   "execution_count": 3,
   "metadata": {},
   "outputs": [],
   "source": [
    "import tensorflow.keras as keras\n",
    "\n",
    "import numpy as np\n",
    "import pickle\n",
    "import cv2\n",
    "from os import listdir\n",
    "from sklearn.preprocessing import LabelBinarizer\n",
    "from keras.models import Sequential\n",
    "from tensorflow.keras.layers import BatchNormalization\n",
    "from keras.layers.convolutional import Conv2D\n",
    "from keras.layers.convolutional import MaxPooling2D\n",
    "from keras.layers.core import Activation, Flatten, Dropout, Dense\n",
    "from keras import backend as K\n",
    "from keras.preprocessing.image import ImageDataGenerator\n",
    "from tensorflow.keras.optimizers import Adam\n",
    "from keras.preprocessing import image\n",
    "from keras.preprocessing.image import img_to_array\n",
    "from sklearn.preprocessing import MultiLabelBinarizer\n",
    "from sklearn.model_selection import train_test_split\n",
    "import matplotlib.pyplot as plt"
   ]
  },
  {
   "cell_type": "code",
   "execution_count": 4,
   "metadata": {},
   "outputs": [],
   "source": [
    "width=256\n",
    "height=256\n",
    "depth=3\n",
    "inputShape = (height, width, depth)\n",
    "chanDim = -1\n",
    "if K.image_data_format() == \"channels_first\":\n",
    "    inputShape = (depth, height, width)\n",
    "    chanDim = 1"
   ]
  },
  {
   "cell_type": "code",
   "execution_count": 5,
   "metadata": {},
   "outputs": [],
   "source": [
    "from sklearn.preprocessing import LabelBinarizer\n",
    "import pickle\n",
    "\n",
    "file_name2 = r\"C:\\Users\\User\\Desktop\\Sem 2 2021\\Projek Sarjana Muda\\Bot Model\\label_list.pkl\"\n",
    "open_file = open(file_name2, \"rb\")\n",
    "label_list = pickle.load(open_file)\n",
    "open_file.close()\n",
    "\n",
    "label_binarizer = LabelBinarizer()\n",
    "image_labels = label_binarizer.fit_transform(label_list)\n",
    "pickle.dump(label_binarizer,open('label_transform.pkl', 'wb'))\n",
    "n_classes = len(label_binarizer.classes_)"
   ]
  },
  {
   "cell_type": "code",
   "execution_count": 6,
   "metadata": {},
   "outputs": [],
   "source": [
    "label_binarizer = LabelBinarizer()\n",
    "image_labels = label_binarizer.fit_transform(label_list)\n",
    "pickle.dump(label_binarizer,open('label_transform.pkl', 'wb'))\n",
    "n_classes = len(label_binarizer.classes_)"
   ]
  },
  {
   "cell_type": "code",
   "execution_count": 7,
   "metadata": {},
   "outputs": [],
   "source": [
    "# Building the model.\n",
    "model = Sequential()\n",
    "model.add(Conv2D(32, (3, 3), padding=\"same\",input_shape=inputShape)) # First convolutional layer\n",
    "model.add(Activation(\"relu\"))\n",
    "model.add(BatchNormalization(axis=chanDim))\n",
    "model.add(MaxPooling2D(pool_size=(3, 3)))\n",
    "model.add(Dropout(0.25))\n",
    "\n",
    "model.add(Conv2D(64, (3, 3), padding=\"same\")) # Second convolutional layer\n",
    "model.add(Activation(\"relu\"))\n",
    "model.add(BatchNormalization(axis=chanDim))\n",
    "\n",
    "model.add(Conv2D(64, (3, 3), padding=\"same\")) # Third convolutional layer\n",
    "model.add(Activation(\"relu\"))\n",
    "model.add(BatchNormalization(axis=chanDim))\n",
    "model.add(MaxPooling2D(pool_size=(2, 2)))\n",
    "model.add(Dropout(0.25))\n",
    "\n",
    "model.add(Conv2D(128, (3, 3), padding=\"same\")) # Fourth convolutional layer\n",
    "model.add(Activation(\"relu\"))\n",
    "model.add(BatchNormalization(axis=chanDim))\n",
    "\n",
    "model.add(Conv2D(128, (3, 3), padding=\"same\")) # Fifth convolutional layer\n",
    "model.add(Activation(\"relu\"))\n",
    "model.add(BatchNormalization(axis=chanDim))\n",
    "model.add(MaxPooling2D(pool_size=(2, 2)))\n",
    "model.add(Dropout(0.25))\n",
    "model.add(Flatten())\n",
    "\n",
    "model.add(Dense(1024, kernel_regularizer='l2')) # sixth layer (Dense)\n",
    "model.add(Activation(\"relu\"))\n",
    "model.add(BatchNormalization())\n",
    "model.add(Dropout(0.5))\n",
    "\n",
    "model.add(Dense(n_classes)) # Seventh layer (output)\n",
    "model.add(Activation(\"softmax\"))"
   ]
  },
  {
   "cell_type": "code",
   "execution_count": 8,
   "metadata": {},
   "outputs": [],
   "source": [
    "#from tensorflow import keras\n",
    "model.load_weights(r'C:\\Users\\User\\Desktop\\Sem 2 2021\\Projek Sarjana Muda\\Bot Model\\AdamModel.h5')"
   ]
  },
  {
   "cell_type": "code",
   "execution_count": 9,
   "metadata": {},
   "outputs": [],
   "source": [
    "import cv2\n",
    "import numpy as np\n",
    "from cv2 import *\n",
    "default_image_size = tuple((256, 256))"
   ]
  },
  {
   "cell_type": "code",
   "execution_count": null,
   "metadata": {},
   "outputs": [
    {
     "name": "stderr",
     "output_type": "stream",
     "text": [
      "2021-09-08 13:19:52,246 - apscheduler.scheduler - INFO - Scheduler started\n",
      "2021-09-08 14:57:13,206 - telegram.vendor.ptb_urllib3.urllib3.connectionpool - WARNING - Retrying (Retry(total=2, connect=None, read=None, redirect=None)) after connection broken by 'NewConnectionError('<telegram.vendor.ptb_urllib3.urllib3.connection.VerifiedHTTPSConnection object at 0x000001B5FFFE15B0>: Failed to establish a new connection: [Errno 11001] getaddrinfo failed')': /bot1727473991:AAHaAA4OmJdFjXJGEx3SeoL7xNhHfq0IEKs/getUpdates\n",
      "2021-09-08 14:57:13,222 - telegram.vendor.ptb_urllib3.urllib3.connectionpool - WARNING - Retrying (Retry(total=1, connect=None, read=None, redirect=None)) after connection broken by 'NewConnectionError('<telegram.vendor.ptb_urllib3.urllib3.connection.VerifiedHTTPSConnection object at 0x000001B5FFFE1F10>: Failed to establish a new connection: [Errno 11001] getaddrinfo failed')': /bot1727473991:AAHaAA4OmJdFjXJGEx3SeoL7xNhHfq0IEKs/getUpdates\n",
      "2021-09-08 14:57:13,225 - telegram.vendor.ptb_urllib3.urllib3.connectionpool - WARNING - Retrying (Retry(total=0, connect=None, read=None, redirect=None)) after connection broken by 'NewConnectionError('<telegram.vendor.ptb_urllib3.urllib3.connection.VerifiedHTTPSConnection object at 0x000001B5FFFE1490>: Failed to establish a new connection: [Errno 11001] getaddrinfo failed')': /bot1727473991:AAHaAA4OmJdFjXJGEx3SeoL7xNhHfq0IEKs/getUpdates\n",
      "2021-09-08 14:57:13,227 - telegram.ext.updater - ERROR - Error while getting Updates: urllib3 HTTPError HTTPSConnectionPool(host='api.telegram.org', port=443): Max retries exceeded with url: /bot1727473991:AAHaAA4OmJdFjXJGEx3SeoL7xNhHfq0IEKs/getUpdates (Caused by NewConnectionError('<telegram.vendor.ptb_urllib3.urllib3.connection.VerifiedHTTPSConnection object at 0x000001B5FFFE1550>: Failed to establish a new connection: [Errno 11001] getaddrinfo failed'))\n",
      "2021-09-08 14:57:13,229 - __main__ - WARNING - Update \"None\" caused error \"urllib3 HTTPError HTTPSConnectionPool(host='api.telegram.org', port=443): Max retries exceeded with url: /bot1727473991:AAHaAA4OmJdFjXJGEx3SeoL7xNhHfq0IEKs/getUpdates (Caused by NewConnectionError('<telegram.vendor.ptb_urllib3.urllib3.connection.VerifiedHTTPSConnection object at 0x000001B5FFFE1550>: Failed to establish a new connection: [Errno 11001] getaddrinfo failed'))\"\n",
      "2021-09-08 14:57:14,232 - telegram.vendor.ptb_urllib3.urllib3.connectionpool - WARNING - Retrying (Retry(total=2, connect=None, read=None, redirect=None)) after connection broken by 'NewConnectionError('<telegram.vendor.ptb_urllib3.urllib3.connection.VerifiedHTTPSConnection object at 0x000001B5FFFE1D60>: Failed to establish a new connection: [Errno 11001] getaddrinfo failed')': /bot1727473991:AAHaAA4OmJdFjXJGEx3SeoL7xNhHfq0IEKs/getUpdates\n",
      "2021-09-08 14:57:14,235 - telegram.vendor.ptb_urllib3.urllib3.connectionpool - WARNING - Retrying (Retry(total=1, connect=None, read=None, redirect=None)) after connection broken by 'NewConnectionError('<telegram.vendor.ptb_urllib3.urllib3.connection.VerifiedHTTPSConnection object at 0x000001B5FFFE1700>: Failed to establish a new connection: [Errno 11001] getaddrinfo failed')': /bot1727473991:AAHaAA4OmJdFjXJGEx3SeoL7xNhHfq0IEKs/getUpdates\n",
      "2021-09-08 14:57:14,238 - telegram.vendor.ptb_urllib3.urllib3.connectionpool - WARNING - Retrying (Retry(total=0, connect=None, read=None, redirect=None)) after connection broken by 'NewConnectionError('<telegram.vendor.ptb_urllib3.urllib3.connection.VerifiedHTTPSConnection object at 0x000001B5FFFE1580>: Failed to establish a new connection: [Errno 11001] getaddrinfo failed')': /bot1727473991:AAHaAA4OmJdFjXJGEx3SeoL7xNhHfq0IEKs/getUpdates\n",
      "2021-09-08 14:57:14,241 - telegram.ext.updater - ERROR - Error while getting Updates: urllib3 HTTPError HTTPSConnectionPool(host='api.telegram.org', port=443): Max retries exceeded with url: /bot1727473991:AAHaAA4OmJdFjXJGEx3SeoL7xNhHfq0IEKs/getUpdates (Caused by NewConnectionError('<telegram.vendor.ptb_urllib3.urllib3.connection.VerifiedHTTPSConnection object at 0x000001B601485E20>: Failed to establish a new connection: [Errno 11001] getaddrinfo failed'))\n",
      "2021-09-08 14:57:14,253 - __main__ - WARNING - Update \"None\" caused error \"urllib3 HTTPError HTTPSConnectionPool(host='api.telegram.org', port=443): Max retries exceeded with url: /bot1727473991:AAHaAA4OmJdFjXJGEx3SeoL7xNhHfq0IEKs/getUpdates (Caused by NewConnectionError('<telegram.vendor.ptb_urllib3.urllib3.connection.VerifiedHTTPSConnection object at 0x000001B601485E20>: Failed to establish a new connection: [Errno 11001] getaddrinfo failed'))\"\n",
      "2021-09-08 14:57:15,756 - telegram.vendor.ptb_urllib3.urllib3.connectionpool - WARNING - Retrying (Retry(total=2, connect=None, read=None, redirect=None)) after connection broken by 'NewConnectionError('<telegram.vendor.ptb_urllib3.urllib3.connection.VerifiedHTTPSConnection object at 0x000001B6018C3970>: Failed to establish a new connection: [Errno 11001] getaddrinfo failed')': /bot1727473991:AAHaAA4OmJdFjXJGEx3SeoL7xNhHfq0IEKs/getUpdates\n",
      "2021-09-08 14:57:15,758 - telegram.vendor.ptb_urllib3.urllib3.connectionpool - WARNING - Retrying (Retry(total=1, connect=None, read=None, redirect=None)) after connection broken by 'NewConnectionError('<telegram.vendor.ptb_urllib3.urllib3.connection.VerifiedHTTPSConnection object at 0x000001B601485820>: Failed to establish a new connection: [Errno 11001] getaddrinfo failed')': /bot1727473991:AAHaAA4OmJdFjXJGEx3SeoL7xNhHfq0IEKs/getUpdates\n",
      "2021-09-08 14:57:15,760 - telegram.vendor.ptb_urllib3.urllib3.connectionpool - WARNING - Retrying (Retry(total=0, connect=None, read=None, redirect=None)) after connection broken by 'NewConnectionError('<telegram.vendor.ptb_urllib3.urllib3.connection.VerifiedHTTPSConnection object at 0x000001B6014853D0>: Failed to establish a new connection: [Errno 11001] getaddrinfo failed')': /bot1727473991:AAHaAA4OmJdFjXJGEx3SeoL7xNhHfq0IEKs/getUpdates\n",
      "2021-09-08 14:57:15,762 - telegram.ext.updater - ERROR - Error while getting Updates: urllib3 HTTPError HTTPSConnectionPool(host='api.telegram.org', port=443): Max retries exceeded with url: /bot1727473991:AAHaAA4OmJdFjXJGEx3SeoL7xNhHfq0IEKs/getUpdates (Caused by NewConnectionError('<telegram.vendor.ptb_urllib3.urllib3.connection.VerifiedHTTPSConnection object at 0x000001B6014856D0>: Failed to establish a new connection: [Errno 11001] getaddrinfo failed'))\n",
      "2021-09-08 14:57:15,764 - __main__ - WARNING - Update \"None\" caused error \"urllib3 HTTPError HTTPSConnectionPool(host='api.telegram.org', port=443): Max retries exceeded with url: /bot1727473991:AAHaAA4OmJdFjXJGEx3SeoL7xNhHfq0IEKs/getUpdates (Caused by NewConnectionError('<telegram.vendor.ptb_urllib3.urllib3.connection.VerifiedHTTPSConnection object at 0x000001B6014856D0>: Failed to establish a new connection: [Errno 11001] getaddrinfo failed'))\"\n",
      "2021-09-08 14:57:18,017 - telegram.vendor.ptb_urllib3.urllib3.connectionpool - WARNING - Retrying (Retry(total=2, connect=None, read=None, redirect=None)) after connection broken by 'NewConnectionError('<telegram.vendor.ptb_urllib3.urllib3.connection.VerifiedHTTPSConnection object at 0x000001B601485E20>: Failed to establish a new connection: [Errno 11001] getaddrinfo failed')': /bot1727473991:AAHaAA4OmJdFjXJGEx3SeoL7xNhHfq0IEKs/getUpdates\n",
      "2021-09-08 14:57:18,019 - telegram.vendor.ptb_urllib3.urllib3.connectionpool - WARNING - Retrying (Retry(total=1, connect=None, read=None, redirect=None)) after connection broken by 'NewConnectionError('<telegram.vendor.ptb_urllib3.urllib3.connection.VerifiedHTTPSConnection object at 0x000001B601485EB0>: Failed to establish a new connection: [Errno 11001] getaddrinfo failed')': /bot1727473991:AAHaAA4OmJdFjXJGEx3SeoL7xNhHfq0IEKs/getUpdates\n",
      "2021-09-08 14:57:18,021 - telegram.vendor.ptb_urllib3.urllib3.connectionpool - WARNING - Retrying (Retry(total=0, connect=None, read=None, redirect=None)) after connection broken by 'NewConnectionError('<telegram.vendor.ptb_urllib3.urllib3.connection.VerifiedHTTPSConnection object at 0x000001B601485C40>: Failed to establish a new connection: [Errno 11001] getaddrinfo failed')': /bot1727473991:AAHaAA4OmJdFjXJGEx3SeoL7xNhHfq0IEKs/getUpdates\n",
      "2021-09-08 14:57:18,029 - telegram.ext.updater - ERROR - Error while getting Updates: urllib3 HTTPError HTTPSConnectionPool(host='api.telegram.org', port=443): Max retries exceeded with url: /bot1727473991:AAHaAA4OmJdFjXJGEx3SeoL7xNhHfq0IEKs/getUpdates (Caused by NewConnectionError('<telegram.vendor.ptb_urllib3.urllib3.connection.VerifiedHTTPSConnection object at 0x000001B60193F250>: Failed to establish a new connection: [Errno 11001] getaddrinfo failed'))\n"
     ]
    },
    {
     "name": "stderr",
     "output_type": "stream",
     "text": [
      "2021-09-08 14:57:18,030 - __main__ - WARNING - Update \"None\" caused error \"urllib3 HTTPError HTTPSConnectionPool(host='api.telegram.org', port=443): Max retries exceeded with url: /bot1727473991:AAHaAA4OmJdFjXJGEx3SeoL7xNhHfq0IEKs/getUpdates (Caused by NewConnectionError('<telegram.vendor.ptb_urllib3.urllib3.connection.VerifiedHTTPSConnection object at 0x000001B60193F250>: Failed to establish a new connection: [Errno 11001] getaddrinfo failed'))\"\n",
      "2021-09-08 14:57:21,459 - telegram.vendor.ptb_urllib3.urllib3.connectionpool - WARNING - Retrying (Retry(total=2, connect=None, read=None, redirect=None)) after connection broken by 'NewConnectionError('<telegram.vendor.ptb_urllib3.urllib3.connection.VerifiedHTTPSConnection object at 0x000001B5FE577460>: Failed to establish a new connection: [Errno 11001] getaddrinfo failed')': /bot1727473991:AAHaAA4OmJdFjXJGEx3SeoL7xNhHfq0IEKs/getUpdates\n",
      "2021-09-08 14:57:21,483 - telegram.vendor.ptb_urllib3.urllib3.connectionpool - WARNING - Retrying (Retry(total=1, connect=None, read=None, redirect=None)) after connection broken by 'NewConnectionError('<telegram.vendor.ptb_urllib3.urllib3.connection.VerifiedHTTPSConnection object at 0x000001B6013DEBE0>: Failed to establish a new connection: [Errno 11001] getaddrinfo failed')': /bot1727473991:AAHaAA4OmJdFjXJGEx3SeoL7xNhHfq0IEKs/getUpdates\n",
      "2021-09-08 14:57:21,494 - telegram.vendor.ptb_urllib3.urllib3.connectionpool - WARNING - Retrying (Retry(total=0, connect=None, read=None, redirect=None)) after connection broken by 'NewConnectionError('<telegram.vendor.ptb_urllib3.urllib3.connection.VerifiedHTTPSConnection object at 0x000001B5FFFE1D90>: Failed to establish a new connection: [Errno 11001] getaddrinfo failed')': /bot1727473991:AAHaAA4OmJdFjXJGEx3SeoL7xNhHfq0IEKs/getUpdates\n",
      "2021-09-08 14:57:21,499 - telegram.ext.updater - ERROR - Error while getting Updates: urllib3 HTTPError HTTPSConnectionPool(host='api.telegram.org', port=443): Max retries exceeded with url: /bot1727473991:AAHaAA4OmJdFjXJGEx3SeoL7xNhHfq0IEKs/getUpdates (Caused by NewConnectionError('<telegram.vendor.ptb_urllib3.urllib3.connection.VerifiedHTTPSConnection object at 0x000001B5FFFE1970>: Failed to establish a new connection: [Errno 11001] getaddrinfo failed'))\n",
      "2021-09-08 14:57:21,501 - __main__ - WARNING - Update \"None\" caused error \"urllib3 HTTPError HTTPSConnectionPool(host='api.telegram.org', port=443): Max retries exceeded with url: /bot1727473991:AAHaAA4OmJdFjXJGEx3SeoL7xNhHfq0IEKs/getUpdates (Caused by NewConnectionError('<telegram.vendor.ptb_urllib3.urllib3.connection.VerifiedHTTPSConnection object at 0x000001B5FFFE1970>: Failed to establish a new connection: [Errno 11001] getaddrinfo failed'))\"\n",
      "2021-09-08 14:57:26,576 - telegram.vendor.ptb_urllib3.urllib3.connectionpool - WARNING - Retrying (Retry(total=2, connect=None, read=None, redirect=None)) after connection broken by 'NewConnectionError('<telegram.vendor.ptb_urllib3.urllib3.connection.VerifiedHTTPSConnection object at 0x000001B5FE577430>: Failed to establish a new connection: [Errno 11001] getaddrinfo failed')': /bot1727473991:AAHaAA4OmJdFjXJGEx3SeoL7xNhHfq0IEKs/getUpdates\n",
      "2021-09-08 14:57:26,577 - telegram.vendor.ptb_urllib3.urllib3.connectionpool - WARNING - Retrying (Retry(total=1, connect=None, read=None, redirect=None)) after connection broken by 'NewConnectionError('<telegram.vendor.ptb_urllib3.urllib3.connection.VerifiedHTTPSConnection object at 0x000001B5FFFE1610>: Failed to establish a new connection: [Errno 11001] getaddrinfo failed')': /bot1727473991:AAHaAA4OmJdFjXJGEx3SeoL7xNhHfq0IEKs/getUpdates\n",
      "2021-09-08 14:57:26,578 - telegram.vendor.ptb_urllib3.urllib3.connectionpool - WARNING - Retrying (Retry(total=0, connect=None, read=None, redirect=None)) after connection broken by 'NewConnectionError('<telegram.vendor.ptb_urllib3.urllib3.connection.VerifiedHTTPSConnection object at 0x000001B5FFFE1490>: Failed to establish a new connection: [Errno 11001] getaddrinfo failed')': /bot1727473991:AAHaAA4OmJdFjXJGEx3SeoL7xNhHfq0IEKs/getUpdates\n",
      "2021-09-08 14:57:26,579 - telegram.ext.updater - ERROR - Error while getting Updates: urllib3 HTTPError HTTPSConnectionPool(host='api.telegram.org', port=443): Max retries exceeded with url: /bot1727473991:AAHaAA4OmJdFjXJGEx3SeoL7xNhHfq0IEKs/getUpdates (Caused by NewConnectionError('<telegram.vendor.ptb_urllib3.urllib3.connection.VerifiedHTTPSConnection object at 0x000001B5FFFE1C70>: Failed to establish a new connection: [Errno 11001] getaddrinfo failed'))\n",
      "2021-09-08 14:57:26,580 - __main__ - WARNING - Update \"None\" caused error \"urllib3 HTTPError HTTPSConnectionPool(host='api.telegram.org', port=443): Max retries exceeded with url: /bot1727473991:AAHaAA4OmJdFjXJGEx3SeoL7xNhHfq0IEKs/getUpdates (Caused by NewConnectionError('<telegram.vendor.ptb_urllib3.urllib3.connection.VerifiedHTTPSConnection object at 0x000001B5FFFE1C70>: Failed to establish a new connection: [Errno 11001] getaddrinfo failed'))\"\n",
      "2021-09-08 14:57:34,183 - telegram.vendor.ptb_urllib3.urllib3.connectionpool - WARNING - Retrying (Retry(total=2, connect=None, read=None, redirect=None)) after connection broken by 'NewConnectionError('<telegram.vendor.ptb_urllib3.urllib3.connection.VerifiedHTTPSConnection object at 0x000001B5FFFE1A60>: Failed to establish a new connection: [Errno 11001] getaddrinfo failed')': /bot1727473991:AAHaAA4OmJdFjXJGEx3SeoL7xNhHfq0IEKs/getUpdates\n",
      "2021-09-08 14:57:34,184 - telegram.vendor.ptb_urllib3.urllib3.connectionpool - WARNING - Retrying (Retry(total=1, connect=None, read=None, redirect=None)) after connection broken by 'NewConnectionError('<telegram.vendor.ptb_urllib3.urllib3.connection.VerifiedHTTPSConnection object at 0x000001B5FFFE1AC0>: Failed to establish a new connection: [Errno 11001] getaddrinfo failed')': /bot1727473991:AAHaAA4OmJdFjXJGEx3SeoL7xNhHfq0IEKs/getUpdates\n",
      "2021-09-08 14:57:34,185 - telegram.vendor.ptb_urllib3.urllib3.connectionpool - WARNING - Retrying (Retry(total=0, connect=None, read=None, redirect=None)) after connection broken by 'NewConnectionError('<telegram.vendor.ptb_urllib3.urllib3.connection.VerifiedHTTPSConnection object at 0x000001B5FFFE14F0>: Failed to establish a new connection: [Errno 11001] getaddrinfo failed')': /bot1727473991:AAHaAA4OmJdFjXJGEx3SeoL7xNhHfq0IEKs/getUpdates\n",
      "2021-09-08 14:57:34,186 - telegram.ext.updater - ERROR - Error while getting Updates: urllib3 HTTPError HTTPSConnectionPool(host='api.telegram.org', port=443): Max retries exceeded with url: /bot1727473991:AAHaAA4OmJdFjXJGEx3SeoL7xNhHfq0IEKs/getUpdates (Caused by NewConnectionError('<telegram.vendor.ptb_urllib3.urllib3.connection.VerifiedHTTPSConnection object at 0x000001B601485D30>: Failed to establish a new connection: [Errno 11001] getaddrinfo failed'))\n",
      "2021-09-08 14:57:34,187 - __main__ - WARNING - Update \"None\" caused error \"urllib3 HTTPError HTTPSConnectionPool(host='api.telegram.org', port=443): Max retries exceeded with url: /bot1727473991:AAHaAA4OmJdFjXJGEx3SeoL7xNhHfq0IEKs/getUpdates (Caused by NewConnectionError('<telegram.vendor.ptb_urllib3.urllib3.connection.VerifiedHTTPSConnection object at 0x000001B601485D30>: Failed to establish a new connection: [Errno 11001] getaddrinfo failed'))\"\n",
      "2021-09-08 14:57:45,583 - telegram.vendor.ptb_urllib3.urllib3.connectionpool - WARNING - Retrying (Retry(total=2, connect=None, read=None, redirect=None)) after connection broken by 'NewConnectionError('<telegram.vendor.ptb_urllib3.urllib3.connection.VerifiedHTTPSConnection object at 0x000001B5FFFE1E50>: Failed to establish a new connection: [Errno 11001] getaddrinfo failed')': /bot1727473991:AAHaAA4OmJdFjXJGEx3SeoL7xNhHfq0IEKs/getUpdates\n",
      "2021-09-08 14:57:45,583 - telegram.vendor.ptb_urllib3.urllib3.connectionpool - WARNING - Retrying (Retry(total=1, connect=None, read=None, redirect=None)) after connection broken by 'NewConnectionError('<telegram.vendor.ptb_urllib3.urllib3.connection.VerifiedHTTPSConnection object at 0x000001B601485A00>: Failed to establish a new connection: [Errno 11001] getaddrinfo failed')': /bot1727473991:AAHaAA4OmJdFjXJGEx3SeoL7xNhHfq0IEKs/getUpdates\n",
      "2021-09-08 14:57:45,584 - telegram.vendor.ptb_urllib3.urllib3.connectionpool - WARNING - Retrying (Retry(total=0, connect=None, read=None, redirect=None)) after connection broken by 'NewConnectionError('<telegram.vendor.ptb_urllib3.urllib3.connection.VerifiedHTTPSConnection object at 0x000001B6015852B0>: Failed to establish a new connection: [Errno 11001] getaddrinfo failed')': /bot1727473991:AAHaAA4OmJdFjXJGEx3SeoL7xNhHfq0IEKs/getUpdates\n"
     ]
    },
    {
     "name": "stderr",
     "output_type": "stream",
     "text": [
      "2021-09-08 14:57:45,585 - telegram.ext.updater - ERROR - Error while getting Updates: urllib3 HTTPError HTTPSConnectionPool(host='api.telegram.org', port=443): Max retries exceeded with url: /bot1727473991:AAHaAA4OmJdFjXJGEx3SeoL7xNhHfq0IEKs/getUpdates (Caused by NewConnectionError('<telegram.vendor.ptb_urllib3.urllib3.connection.VerifiedHTTPSConnection object at 0x000001B6015854C0>: Failed to establish a new connection: [Errno 11001] getaddrinfo failed'))\n",
      "2021-09-08 14:57:45,585 - __main__ - WARNING - Update \"None\" caused error \"urllib3 HTTPError HTTPSConnectionPool(host='api.telegram.org', port=443): Max retries exceeded with url: /bot1727473991:AAHaAA4OmJdFjXJGEx3SeoL7xNhHfq0IEKs/getUpdates (Caused by NewConnectionError('<telegram.vendor.ptb_urllib3.urllib3.connection.VerifiedHTTPSConnection object at 0x000001B6015854C0>: Failed to establish a new connection: [Errno 11001] getaddrinfo failed'))\"\n",
      "2021-09-08 14:58:02,677 - telegram.vendor.ptb_urllib3.urllib3.connectionpool - WARNING - Retrying (Retry(total=2, connect=None, read=None, redirect=None)) after connection broken by 'NewConnectionError('<telegram.vendor.ptb_urllib3.urllib3.connection.VerifiedHTTPSConnection object at 0x000001B5FFFE1C70>: Failed to establish a new connection: [Errno 11001] getaddrinfo failed')': /bot1727473991:AAHaAA4OmJdFjXJGEx3SeoL7xNhHfq0IEKs/getUpdates\n",
      "2021-09-08 14:58:02,678 - telegram.vendor.ptb_urllib3.urllib3.connectionpool - WARNING - Retrying (Retry(total=1, connect=None, read=None, redirect=None)) after connection broken by 'NewConnectionError('<telegram.vendor.ptb_urllib3.urllib3.connection.VerifiedHTTPSConnection object at 0x000001B6015857F0>: Failed to establish a new connection: [Errno 11001] getaddrinfo failed')': /bot1727473991:AAHaAA4OmJdFjXJGEx3SeoL7xNhHfq0IEKs/getUpdates\n",
      "2021-09-08 14:58:02,679 - telegram.vendor.ptb_urllib3.urllib3.connectionpool - WARNING - Retrying (Retry(total=0, connect=None, read=None, redirect=None)) after connection broken by 'NewConnectionError('<telegram.vendor.ptb_urllib3.urllib3.connection.VerifiedHTTPSConnection object at 0x000001B601585580>: Failed to establish a new connection: [Errno 11001] getaddrinfo failed')': /bot1727473991:AAHaAA4OmJdFjXJGEx3SeoL7xNhHfq0IEKs/getUpdates\n",
      "2021-09-08 14:58:02,680 - telegram.ext.updater - ERROR - Error while getting Updates: urllib3 HTTPError HTTPSConnectionPool(host='api.telegram.org', port=443): Max retries exceeded with url: /bot1727473991:AAHaAA4OmJdFjXJGEx3SeoL7xNhHfq0IEKs/getUpdates (Caused by NewConnectionError('<telegram.vendor.ptb_urllib3.urllib3.connection.VerifiedHTTPSConnection object at 0x000001B601585790>: Failed to establish a new connection: [Errno 11001] getaddrinfo failed'))\n",
      "2021-09-08 14:58:02,681 - __main__ - WARNING - Update \"None\" caused error \"urllib3 HTTPError HTTPSConnectionPool(host='api.telegram.org', port=443): Max retries exceeded with url: /bot1727473991:AAHaAA4OmJdFjXJGEx3SeoL7xNhHfq0IEKs/getUpdates (Caused by NewConnectionError('<telegram.vendor.ptb_urllib3.urllib3.connection.VerifiedHTTPSConnection object at 0x000001B601585790>: Failed to establish a new connection: [Errno 11001] getaddrinfo failed'))\"\n",
      "2021-09-08 14:58:28,320 - telegram.vendor.ptb_urllib3.urllib3.connectionpool - WARNING - Retrying (Retry(total=2, connect=None, read=None, redirect=None)) after connection broken by 'NewConnectionError('<telegram.vendor.ptb_urllib3.urllib3.connection.VerifiedHTTPSConnection object at 0x000001B601585AF0>: Failed to establish a new connection: [Errno 11001] getaddrinfo failed')': /bot1727473991:AAHaAA4OmJdFjXJGEx3SeoL7xNhHfq0IEKs/getUpdates\n",
      "2021-09-08 14:58:28,321 - telegram.vendor.ptb_urllib3.urllib3.connectionpool - WARNING - Retrying (Retry(total=1, connect=None, read=None, redirect=None)) after connection broken by 'NewConnectionError('<telegram.vendor.ptb_urllib3.urllib3.connection.VerifiedHTTPSConnection object at 0x000001B601585700>: Failed to establish a new connection: [Errno 11001] getaddrinfo failed')': /bot1727473991:AAHaAA4OmJdFjXJGEx3SeoL7xNhHfq0IEKs/getUpdates\n",
      "2021-09-08 14:58:28,322 - telegram.vendor.ptb_urllib3.urllib3.connectionpool - WARNING - Retrying (Retry(total=0, connect=None, read=None, redirect=None)) after connection broken by 'NewConnectionError('<telegram.vendor.ptb_urllib3.urllib3.connection.VerifiedHTTPSConnection object at 0x000001B601585220>: Failed to establish a new connection: [Errno 11001] getaddrinfo failed')': /bot1727473991:AAHaAA4OmJdFjXJGEx3SeoL7xNhHfq0IEKs/getUpdates\n",
      "2021-09-08 14:58:28,323 - telegram.ext.updater - ERROR - Error while getting Updates: urllib3 HTTPError HTTPSConnectionPool(host='api.telegram.org', port=443): Max retries exceeded with url: /bot1727473991:AAHaAA4OmJdFjXJGEx3SeoL7xNhHfq0IEKs/getUpdates (Caused by NewConnectionError('<telegram.vendor.ptb_urllib3.urllib3.connection.VerifiedHTTPSConnection object at 0x000001B5FFFE3FA0>: Failed to establish a new connection: [Errno 11001] getaddrinfo failed'))\n",
      "2021-09-08 14:58:28,323 - __main__ - WARNING - Update \"None\" caused error \"urllib3 HTTPError HTTPSConnectionPool(host='api.telegram.org', port=443): Max retries exceeded with url: /bot1727473991:AAHaAA4OmJdFjXJGEx3SeoL7xNhHfq0IEKs/getUpdates (Caused by NewConnectionError('<telegram.vendor.ptb_urllib3.urllib3.connection.VerifiedHTTPSConnection object at 0x000001B5FFFE3FA0>: Failed to establish a new connection: [Errno 11001] getaddrinfo failed'))\"\n",
      "2021-09-08 14:59:06,784 - telegram.vendor.ptb_urllib3.urllib3.connectionpool - WARNING - Retrying (Retry(total=2, connect=None, read=None, redirect=None)) after connection broken by 'NewConnectionError('<telegram.vendor.ptb_urllib3.urllib3.connection.VerifiedHTTPSConnection object at 0x000001B601585550>: Failed to establish a new connection: [Errno 11001] getaddrinfo failed')': /bot1727473991:AAHaAA4OmJdFjXJGEx3SeoL7xNhHfq0IEKs/getUpdates\n",
      "2021-09-08 14:59:06,785 - telegram.vendor.ptb_urllib3.urllib3.connectionpool - WARNING - Retrying (Retry(total=1, connect=None, read=None, redirect=None)) after connection broken by 'NewConnectionError('<telegram.vendor.ptb_urllib3.urllib3.connection.VerifiedHTTPSConnection object at 0x000001B6014859D0>: Failed to establish a new connection: [Errno 11001] getaddrinfo failed')': /bot1727473991:AAHaAA4OmJdFjXJGEx3SeoL7xNhHfq0IEKs/getUpdates\n",
      "2021-09-08 14:59:06,786 - telegram.vendor.ptb_urllib3.urllib3.connectionpool - WARNING - Retrying (Retry(total=0, connect=None, read=None, redirect=None)) after connection broken by 'NewConnectionError('<telegram.vendor.ptb_urllib3.urllib3.connection.VerifiedHTTPSConnection object at 0x000001B6014851F0>: Failed to establish a new connection: [Errno 11001] getaddrinfo failed')': /bot1727473991:AAHaAA4OmJdFjXJGEx3SeoL7xNhHfq0IEKs/getUpdates\n",
      "2021-09-08 14:59:06,788 - telegram.ext.updater - ERROR - Error while getting Updates: urllib3 HTTPError HTTPSConnectionPool(host='api.telegram.org', port=443): Max retries exceeded with url: /bot1727473991:AAHaAA4OmJdFjXJGEx3SeoL7xNhHfq0IEKs/getUpdates (Caused by NewConnectionError('<telegram.vendor.ptb_urllib3.urllib3.connection.VerifiedHTTPSConnection object at 0x000001B601485B80>: Failed to establish a new connection: [Errno 11001] getaddrinfo failed'))\n",
      "2021-09-08 14:59:06,788 - __main__ - WARNING - Update \"None\" caused error \"urllib3 HTTPError HTTPSConnectionPool(host='api.telegram.org', port=443): Max retries exceeded with url: /bot1727473991:AAHaAA4OmJdFjXJGEx3SeoL7xNhHfq0IEKs/getUpdates (Caused by NewConnectionError('<telegram.vendor.ptb_urllib3.urllib3.connection.VerifiedHTTPSConnection object at 0x000001B601485B80>: Failed to establish a new connection: [Errno 11001] getaddrinfo failed'))\"\n"
     ]
    }
   ],
   "source": [
    "logging.basicConfig(format='%(asctime)s - %(name)s - %(levelname)s - %(message)s',\n",
    "                    level=logging.INFO)\n",
    "\n",
    "logger = logging.getLogger(__name__)\n",
    "\n",
    "bot = telegram.Bot(token=\"1727473991:AAHaAA4OmJdFjXJGEx3SeoL7xNhHfq0IEKs\")\n",
    "updater = Updater(token='1727473991:AAHaAA4OmJdFjXJGEx3SeoL7xNhHfq0IEKs', use_context=True)\n",
    "\n",
    "def sample_responses(input_text):\n",
    "    user_message = str(input_text).lower()\n",
    "    \n",
    "    if user_message in (\"hello\", \"hi\",):\n",
    "        return \"Hey!\"\n",
    "    \n",
    "    if user_message in (\"how are you\", \"how are you?\",):\n",
    "        return \"Im good! Thanks for asking.\"\n",
    "    \n",
    "    if user_message in (\"who are you?\", \"who are you\", \"what are you?\",):\n",
    "        return \"I am PlDD bot that will assist you in diagnosis the leaf disease!\"\n",
    "\n",
    "    if user_message in (\"thank you\", \"thank you!\", \"youre good\", \"thanks\"):\n",
    "        return \"My pleasure!\"\n",
    "    \n",
    "    return \"i dont understand you.\"\n",
    "\n",
    "def start(update, context):\n",
    "    \"\"\"Send a message when the command /start is issued.\"\"\"\n",
    "    update.message.reply_text('Hi! Send an image for classifying the disease.')\n",
    "\n",
    "def photo(update, context):\n",
    "    update.message.reply_text('Image received!')\n",
    "    file = bot.getFile(update.message.photo[-1].file_id)\n",
    "    if file:\n",
    "        file.download('temp.jpg')\n",
    "        \n",
    "        my_picture ='temp.jpg'\n",
    "        my_picture_array = convert_image_to_array(my_picture)\n",
    "        my_picture_array = my_picture_array/225.0\n",
    "        my_picture_array = np.expand_dims(my_picture_array, axis=0)\n",
    "\n",
    "        update.message.reply_text('Processing image..')\n",
    "        prediction = model.predict(my_picture_array)\n",
    "        update.message.reply_text(\"The class that I predict is: \" +label_binarizer.classes_[np.argmax(prediction)])\n",
    "        disease = label_binarizer.classes_[np.argmax(prediction)]\n",
    "        if disease == 'Black measles disease':\n",
    "            update.message.reply_text('black measles or Spanish measles, has long plagued grape growers\\\n",
    " with its cryptic expression of symptoms and, for a long time, a lack of identifiable causal organism(s)', parse_mode='Markdown')\n",
    "            \n",
    "        elif disease == 'Black rot disease':\n",
    "            update.message.reply_text('Black rot, caused by the bacterium Xanthomonas campestris pv. campestris,\\\n",
    " is considered the most serious disease of crucifer crops worldwide', parse_mode='Markdown')\n",
    "            \n",
    "        elif disease == 'Common rust disease':\n",
    "            update.message.reply_text('Common corn rust, caused by the fungus Puccinia sorghi, is the most frequently \\\n",
    "occurring of the two primary rust diseases of corn in the U.S., but it rarely causes significant yield losses \\\n",
    "in Ohio field (dent) corn.', parse_mode='Markdown')\n",
    "            \n",
    "        elif disease == 'Early blight disease':\n",
    "            update.message.reply_text('The causal pathogen of early blight is the fungus Alternaria solani. \\\n",
    "Symptoms of early blight occur on fruit, stem and foliage of tomatoes and stem, foliage and tubers of potatoes. \\\n",
    "Spots on foliage are dark brown with circular rings giving a target appearance. These spots may merge to form dead patches. \\\n",
    "This disease can be differentiated from late blight as white mould-bearing spores do not develop around the foliage spots \\\n",
    "during humid weather conditions.', parse_mode='Markdown')\n",
    "            \n",
    "        elif disease == 'Frogeye spot disease':\n",
    "            update.message.reply_text('frogeye leaf spot are phases of a widespread and damaging disease of apple and crabapple. The fruit rot \\\n",
    "phase is called black rot and on the leaf it is called frogeye leaf spot. The disease can result in losses from a rotting of \\\n",
    "fruit before harvest and in storage, a weakening of the tree from defoliation, and a blighting and dieback of twigs and limbs \\\n",
    "caused by girdling cankers.', parse_mode='Markdown')\n",
    "            \n",
    "        elif disease == 'Gray leaf spot disease':\n",
    "            update.message.reply_text('Gray leaf spot is caused by the fungus Cercospora zeae-maydis. \\\n",
    "Gray leaf spot is favored by wet humid weather as often found in valley microclimates. Symptoms of gray leaf \\\n",
    "spot are usually first noticed in the lower leaves. Initially, lesions of gray leaf spot begin as a small dot with \\\n",
    "a yellow halo.', parse_mode='Markdown')\n",
    "            \n",
    "        elif disease == 'Healthy Leaf':\n",
    "            update.message.reply_text('its a healthy leaf. Take a good care of it!', parse_mode='Markdown')\n",
    "            \n",
    "        elif disease == 'Isariopsis leaf spot disease':\n",
    "            update.message.reply_text('This disease also called Leaf blight disease that cause by pathogen \\\n",
    "Pseudocercospora vitis.', parse_mode='Markdown')\n",
    "            \n",
    "        elif disease == 'Late blight disease':\n",
    "            update.message.reply_text('Late blight, also called potato blight, disease of potato and tomato plants that is caused by the water mold \\\n",
    "Phytophthora infestans. The disease occurs in humid regions with temperatures ranging between 4 and 29 °C (40 and 80 °F). Hot dry\\\n",
    "weather checks its spread. Potato or tomato plants that are infected may rot within two weeks.', parse_mode='Markdown')\n",
    "            \n",
    "        elif disease == 'Leaf scorch disease':\n",
    "            update.message.reply_text('Leaf scorch is caused by the fungus Diplocarpon earliana. Symptoms of leaf scorch consist of numerous small, \\\n",
    "irregular, purplish spots or “blotches” that develop on the upper surface of leaves. The centers of the blotches become brownish. \\\n",
    "Blotches may coalesce until they nearly cover the leaflet, which then appears purplish to reddish to brown.', parse_mode='Markdown')\n",
    "            \n",
    "        elif disease == 'Non leaf':\n",
    "            update.message.reply_text('Please upload a leaf picture!', parse_mode='Markdown')\n",
    "            \n",
    "        elif disease == 'Nothern leaf blight disease':\n",
    "            update.message.reply_text('Northern corn leaf blight (NCLB), caused by the fungus Exserohilum turcicum. \\\n",
    "The fungus causing NCLB overwinters as mycelia and conidia on corn residues left on the soil surface. \\\n",
    "During warm, moist weather in early summer, new conidia are produced on the old corn residue and carried by \\\n",
    "the wind or rain to lower leaves of young corn plants. Infection and disease development are favored by heavy dew, \\\n",
    "frequent rainfall, high humidity, and moderate temperatures.', parse_mode='Markdown')\n",
    "            \n",
    "        elif disease == 'Rust disease':\n",
    "            update.message.reply_text('Rust disease is caused by a fungal parasite that needs living plants to survive. Rust diseases occur most often \\\n",
    "in mild, moist conditions. Rust is spread by spores that are transferred from infected plants to healthy plants. These spores \\\n",
    "can be transferred either by the wind or by water, which is why rust disease often spreads after watering. Wet surfaces \\\n",
    "are also needed to cause infections.', parse_mode='Markdown')\n",
    "            \n",
    "        elif disease == 'Scab disease':\n",
    "            update.message.reply_text('scab disease is caused by the fungus Venturia inaequalis. The apple scab fungus has several host-specific \\\n",
    "strains that can cause disease on one type of plant but not any other. For example, the strain of V. inaequalis that \\\n",
    "infects mountain ash will only infect other mountain ash trees and will not infect crabapple trees. Apple and crabapple \\\n",
    "trees are infected by the same strain of the apple scab fungus because the trees are in the same genus.', parse_mode='Markdown')\n",
    "            \n",
    "        else:\n",
    "            update.message.reply_text('unknown disease')\n",
    "    else:\n",
    "        update.message.reply_text('Image could not be processed....')\n",
    "    \n",
    "def help_command(update, context):\n",
    "    \"\"\"Send a message when the command /help is issued.\"\"\"\n",
    "    update.message.reply_text('you can use this bot to identify the plant disease by sending the picture of the leaf to me!')\n",
    "\n",
    "def handle_message(update, context):\n",
    "    text = str(update.message.text).lower()\n",
    "    response = sample_responses(text)\n",
    "    \n",
    "    update.message.reply_text(response)\n",
    "\n",
    "def error(update, context):\n",
    "    \"\"\"Log Errors caused by Updates.\"\"\"\n",
    "    logger.warning('Update \"%s\" caused error \"%s\"', update, context.error)\n",
    "\n",
    "\n",
    "def main():\n",
    "    \"\"\"Start the bot.\"\"\"\n",
    "    dp = updater.dispatcher\n",
    "\n",
    "    # on different commands - answer in Telegram\n",
    "    dp.add_handler(CommandHandler(\"start\", start))\n",
    "    dp.add_handler(CommandHandler(\"help\", help_command))\n",
    "\n",
    "    # on noncommand i.e message - echo the message on Telegram\n",
    "    dp.add_handler(MessageHandler(Filters.text, handle_message))\n",
    "    dp.add_handler(MessageHandler(Filters.photo, photo))\n",
    "\n",
    "    # log all errors\n",
    "    dp.add_error_handler(error)\n",
    "\n",
    "    # Start the Bot\n",
    "    updater.start_polling()\n",
    "\n",
    "    # Run the bot until you press Ctrl-C or the process receives SIGINT,\n",
    "    # SIGTERM or SIGABRT. This should be used most of the time, since\n",
    "    # start_polling() is non-blocking and will stop the bot gracefully.\n",
    "    updater.idle()\n",
    "\n",
    "\n",
    "if __name__ == '__main__':\n",
    "    main()"
   ]
  },
  {
   "cell_type": "code",
   "execution_count": null,
   "metadata": {},
   "outputs": [],
   "source": []
  }
 ],
 "metadata": {
  "kernelspec": {
   "display_name": "Python 3",
   "language": "python",
   "name": "python3"
  },
  "language_info": {
   "codemirror_mode": {
    "name": "ipython",
    "version": 3
   },
   "file_extension": ".py",
   "mimetype": "text/x-python",
   "name": "python",
   "nbconvert_exporter": "python",
   "pygments_lexer": "ipython3",
   "version": "3.8.3"
  }
 },
 "nbformat": 4,
 "nbformat_minor": 4
}
